INFO: Starting training:
        Epochs:          10
        Batch size:      1
        Learning rate:   1e-05
        Training size:   14
        Validation size: 1
        Checkpoints:     True
        Device:          cpu
        Images scaling:  0.5
        Mixed Precision: True
C:\Users\ryanx\env\deepsort\lib\site-packages\torch\cuda\amp\grad_scaler.py:115: UserWarning: torch.cuda.amp.GradScaler is enabled, but CUDA is not available.  Disabling.
  warnings.warn("torch.cuda.amp.GradScaler is enabled, but CUDA is not available.  Disabling.")
Epoch 1/10:   0%|                                                                                                                                              | 0/14 [00:08<?, ?img/s]
Traceback (most recent call last):
  File "C:\Users\ryanx\OneDrive\桌面\code\Pytorch-UNet\train.py", line 185, in <module>
    train_net(net=net,
  File "C:\Users\ryanx\OneDrive\桌面\code\Pytorch-UNet\train.py", line 79, in train_net
    for batch in train_loader:
  File "C:\Users\ryanx\env\deepsort\lib\site-packages\torch\utils\data\dataloader.py", line 521, in __next__
    data = self._next_data()
  File "C:\Users\ryanx\env\deepsort\lib\site-packages\torch\utils\data\dataloader.py", line 1203, in _next_data
    return self._process_data(data)
  File "C:\Users\ryanx\env\deepsort\lib\site-packages\torch\utils\data\dataloader.py", line 1229, in _process_data
    data.reraise()
  File "C:\Users\ryanx\env\deepsort\lib\site-packages\torch\_utils.py", line 434, in reraise
    raise exception
AssertionError: Caught AssertionError in DataLoader worker process 0.
Original Traceback (most recent call last):
  File "C:\Users\ryanx\env\deepsort\lib\site-packages\torch\utils\data\_utils\worker.py", line 287, in _worker_loop
    data = fetcher.fetch(index)
  File "C:\Users\ryanx\env\deepsort\lib\site-packages\torch\utils\data\_utils\fetch.py", line 49, in fetch
    data = [self.dataset[idx] for idx in possibly_batched_index]
  File "C:\Users\ryanx\env\deepsort\lib\site-packages\torch\utils\data\_utils\fetch.py", line 49, in <listcomp>
    data = [self.dataset[idx] for idx in possibly_batched_index]
  File "C:\Users\ryanx\env\deepsort\lib\site-packages\torch\utils\data\dataset.py", line 363, in __getitem__
    return self.dataset[self.indices[idx]]
  File "C:\Users\ryanx\OneDrive\桌面\code\Pytorch-UNet\utils\data_loading.py", line 61, in __getitem__
    assert len(mask_file) == 1, f'Either no mask or multiple masks found for the ID {name}: {mask_file}'
AssertionError: Either no mask or multiple masks found for the ID 14: []